<mujoco model="ur10">
  <compiler angle="radian" autolimits="true"/>

  <default>
    <default class="ur10">
      <joint axis="0 1 0" range="-6.28319 6.28319" armature="0.1"/>
      <position ctrlrange="-6.2831 6.2831"/>
      <general biastype="affine" ctrlrange="-6.2831 6.2831" gainprm="5000" biasprm="0 -5000 -500"/>
    </default>
    <default class="2f85">
      <mesh scale="0.001 0.001 0.001"/>
      <general biastype="affine"/>
      <site type="sphere" rgba="0.9 0.9 0.9 1" size="0.005" group="4"/>
      <joint axis="1 0 0"/>
      <default class="driver">
        <joint range="0 0.8" armature="0.005" damping="0.1" solimplimit="0.95 0.99 0.001" solreflimit="0.005 1"/>
      </default>
      <default class="follower">
        <joint range="-0.872664 0.872664" pos="0 -0.018 0.0065" solimplimit="0.95 0.99 0.001" solreflimit="0.005 1"/>
      </default>
      <default class="spring_link">
        <joint range="-0.29670597283 0.8" stiffness="0.05" springref="2.62" damping="0.00125"/>
      </default>
      <default class="coupler">
        <joint range="-1.57 0" solimplimit="0.95 0.99 0.001" solreflimit="0.005 1"/>
      </default>
      <default class="2f85/visual">
        <geom type="mesh" contype="0" conaffinity="0" group="2"/>
      </default>
      <default class="2f85/collision">
        <geom type="mesh" group="3"/>
        <default class="pad_box1">
          <geom mass="0" type="box" pos="0 -0.0026 0.028125" size="0.011 0.004 0.009375" friction="0.7"
            solimp="0.95 0.99 0.001" solref="0.004 1" priority="1" rgba="0.55 0.55 0.55 1"/>
        </default>
        <default class="pad_box2">
          <geom mass="0" type="box" pos="0 -0.0026 0.009375" size="0.011 0.004 0.009375" friction="0.6"
            solimp="0.95 0.99 0.001" solref="0.004 1" priority="1" rgba="0.45 0.45 0.45 1"/>
        </default>
      </default>
    </default>
  </default>

  <asset>
    <material name="gray" rgba="0.4627 0.4627 0.4627 1"/>
    <material name="black" rgba="0.149 0.149 0.149 1"/>

    <mesh name="base0" file="universal_robots_ur10/assets/base.stl"/>
    <mesh name="shoulder" file="universal_robots_ur10/assets/shoulder.stl"/>
    <mesh name="upperarm" file="universal_robots_ur10/assets/upperarm.stl"/>
    <mesh name="forearm" file="universal_robots_ur10/assets/forearm.stl"/>
    <mesh name="wrist1" file="universal_robots_ur10/assets/wrist1.stl"/>
    <mesh name="wrist2" file="universal_robots_ur10/assets/wrist2.stl"/>
    <mesh name="wrist3" file="universal_robots_ur10/assets/wrist3.stl"/>

    <mesh class="2f85" file="robotiq_2f85/assets/base_mount.stl"/>
    <mesh class="2f85" file="robotiq_2f85/assets/base.stl"/>
    <mesh class="2f85" file="robotiq_2f85/assets/driver.stl"/>
    <mesh class="2f85" file="robotiq_2f85/assets/coupler.stl"/>
    <mesh class="2f85" file="robotiq_2f85/assets/follower.stl"/>
    <mesh class="2f85" file="robotiq_2f85/assets/pad.stl"/>
    <mesh class="2f85" file="robotiq_2f85/assets/silicone_pad.stl"/>
    <mesh class="2f85" file="robotiq_2f85/assets/spring_link.stl"/>
  </asset>

  <worldbody>
    <body name="base0" childclass="ur10">
      <geom quat="-1 0 0 0" type="mesh" rgba="0.7 0.7 0.7 1" mesh="base0"/>
      <body name="shoulder_link" pos="0 0 0.1273" quat="0 0 0 1">
        <inertial pos="0.021 -0.027 0" quat="0.988634 -0.000680926 0.148578 -0.0229591" mass="7.1" diaginertia="0.0353866 0.0352903 0.0202532"/>
        <joint name="joint1" pos="0 0 0" axis="0 0 1" range="-6.28319 6.28319" damping="10"/>
        <geom quat="0 0 0 1" type="mesh" rgba="0.7 0.7 0.7 1" mesh="shoulder"/>
        <body name="upper_arm_link" quat="0.5 0.5 0.5 -0.5">
          <inertial pos="-0.232 0 0.158" quat="0.500033 0.499784 0.489585 0.510381" mass="12.7" diaginertia="0.77068 0.769758 0.0278114"/>
          <joint name="joint2" pos="0 0 0" axis="0 0 1" range="-6.28319 6.28319" damping="10"/>
          <geom pos="0 0 0.220941" quat="0.5 0.5 -0.5 -0.5" type="mesh" rgba="0.7 0.7 0.7 1" mesh="upperarm"/>
          <body name="forearm_link" pos="-0.612 0 0" quat="1 0 0 1">
            <inertial pos="-0.3323 0 0.068" quat="0.492051 0.507971 0.507346 0.492394" mass="4.27" diaginertia="0.30928 0.306743 0.00985709"/>
            <joint name="joint3" pos="0 0 0" axis="0 0 1" range="-3.14159 3.14159" damping="5"/>
            <geom pos="0 0 0.049042" quat="0.5 0.5 -0.5 -0.5" type="mesh" rgba="0.7 0.7 0.7 1" mesh="forearm"/>
            <body name="wrist_1_link" pos="-0.5723 0 0.163941" quat="1 0 0 -1">
              <inertial pos="0 -0.018 0.007" quat="0.525776 0.850564 -0.0100431 9.45801e-05" mass="2" diaginertia="0.00296017 0.00269992 0.00209991"/>
              <joint name="joint4" pos="0 0 0" axis="0 0 1" range="-6.28319 6.28319" damping="2"/>
              <geom pos="0 0 -0.1149" quat="0.707107 0.707107 0 0" type="mesh" rgba="0.7 0.7 0.7 1" mesh="wrist1"/>
              <body name="wrist_2_link" pos="0 -0.1157 -2.37305e-11" quat="0.5 0.5 0.5 -0.5">
                <inertial pos="0 0.018 -0.007" quat="0.525776 0.850564 -0.0100431 9.45801e-05" mass="2" diaginertia="0.00296017 0.00269992 0.00209991"/>
                <joint name="joint5" pos="0 0 0" axis="0 0 1" range="-6.28319 6.28319" damping="2"/>
                <geom pos="0 0 -0.1158" quat="1 0 0 0" type="mesh" rgba="0.7 0.7 0.7 1" mesh="wrist2"/>
                <body name="wrist_3_link" pos="0 0.0922 -1.89105e-11" quat="0.707107 -0.707107 0 0">
                  <inertial pos="0 0 -0.026" quat="0.707107 0 0 0.707107" mass="0.365" diaginertia="0.00041 0.0004 0.00034"/>
                  <joint name="joint6" pos="0 0 0" axis="0 0 1" range="-6.28319 6.28319" damping="2"/>
                  <geom pos="0 0 -0.0922" quat="0.707107 0.707107 0 0" type="mesh" rgba="0.7 0.7 0.7 1" mesh="wrist3"/>
                  <body name="attachment" pos="0 0 0" quat="0.707107 0 0 0.707107">
                    <camera name="handcam_depth" pos="-0.05 0 0" fovy="62" quat="0 1 -1 0"/>
                    <camera name="handcam_rgb" pos="-0.05 0.015 0" fovy="42.5" quat="0 1 -1 0"/>
                    <site name="attachment_site" quat="0 0 0 1"/>
                    <body name="base_mount" quat="-1 0 0 1" childclass="2f85">
                      <geom class="2f85/visual" mesh="base_mount" material="black"/>
                      <geom class="2f85/collision" mesh="base_mount"/>
                      <body name="base" pos="0 0 0.0038" quat="1 0 0 -1">
                        <inertial mass="0.777441" pos="0 -2.70394e-05 0.0354675" quat="1 -0.00152849 0 0"
                          diaginertia="0.000260285 0.000225381 0.000152708"/>
                        <geom class="2f85/visual" mesh="base" material="black"/>
                        <geom class="2f85/collision" mesh="base"/>
                        <site name="pinch" pos="0 0 0.145"/>
                        <body name="right_driver" pos="0 0.0306011 0.054904">
                          <inertial mass="0.00899563" pos="2.96931e-12 0.0177547 0.00107314"
                            quat="0.681301 0.732003 0 0" diaginertia="1.72352e-06 1.60906e-06 3.22006e-07"/>
                          <joint name="right_driver_joint" class="driver"/>
                          <geom class="2f85/visual" mesh="driver" material="gray"/>
                          <geom class="2f85/collision" mesh="driver"/>
                          <body name="right_coupler" pos="0 0.0315 -0.0041">
                            <inertial mass="0.0140974" pos="0 0.00301209 0.0232175"
                              quat="0.705636 -0.0455904 0.0455904 0.705636"
                              diaginertia="4.16206e-06 3.52216e-06 8.88131e-07"/>
                            <joint name="right_coupler_joint" class="coupler"/>
                            <geom class="2f85/visual" mesh="coupler" material="black"/>
                            <geom class="2f85/collision" mesh="coupler"/>
                          </body>
                        </body>
                        <body name="right_spring_link" pos="0 0.0132 0.0609">
                          <inertial mass="0.0221642" pos="-8.65005e-09 0.0181624 0.0212658"
                            quat="0.663403 -0.244737 0.244737 0.663403"
                            diaginertia="8.96853e-06 6.71733e-06 2.63931e-06"/>
                          <joint name="right_spring_link_joint" class="spring_link"/>
                          <geom class="2f85/visual" mesh="spring_link" material="black"/>
                          <geom class="2f85/collision" mesh="spring_link"/>
                          <body name="right_follower" pos="0 0.055 0.0375">
                            <inertial mass="0.0125222" pos="0 -0.011046 0.0124786" quat="1 0.1664 0 0"
                              diaginertia="2.67415e-06 2.4559e-06 6.02031e-07"/>
                            <joint name="right_follower_joint" class="follower"/>
                            <geom class="2f85/visual" mesh="follower" material="black"/>
                            <geom class="2f85/collision" mesh="follower"/>
                            <body name="right_pad" pos="0 -0.0189 0.01352">
                              <geom class="pad_box1" name="right_pad1"/>
                              <geom class="pad_box2" name="right_pad2"/>
                              <inertial mass="0.0035" pos="0 -0.0025 0.0185" quat="0.707107 0 0 0.707107"
                                diaginertia="4.73958e-07 3.64583e-07 1.23958e-07"/>
                              <geom class="2f85/visual" mesh="pad"/>
                              <body name="right_silicone_pad">
                                <geom class="2f85/visual" mesh="silicone_pad" material="black"/>
                              </body>
                            </body>
                          </body>
                        </body>
                        <body name="left_driver" pos="0 -0.0306011 0.054904" quat="0 0 0 1">
                          <inertial mass="0.00899563" pos="0 0.0177547 0.00107314" quat="0.681301 0.732003 0 0"
                            diaginertia="1.72352e-06 1.60906e-06 3.22006e-07"/>
                          <joint name="left_driver_joint" class="driver"/>
                          <geom class="2f85/visual" mesh="driver" material="gray"/>
                          <geom class="2f85/collision" mesh="driver"/>
                          <body name="left_coupler" pos="0 0.0315 -0.0041">
                            <inertial mass="0.0140974" pos="0 0.00301209 0.0232175"
                              quat="0.705636 -0.0455904 0.0455904 0.705636"
                              diaginertia="4.16206e-06 3.52216e-06 8.88131e-07"/>
                            <joint name="left_coupler_joint" class="coupler"/>
                            <geom class="2f85/visual" mesh="coupler" material="black"/>
                            <geom class="2f85/collision" mesh="coupler"/>
                          </body>
                        </body>
                        <body name="left_spring_link" pos="0 -0.0132 0.0609" quat="0 0 0 1">
                          <inertial mass="0.0221642" pos="-8.65005e-09 0.0181624 0.0212658"
                            quat="0.663403 -0.244737 0.244737 0.663403"
                            diaginertia="8.96853e-06 6.71733e-06 2.63931e-06"/>
                          <joint name="left_spring_link_joint" class="spring_link"/>
                          <geom class="2f85/visual" mesh="spring_link" material="black"/>
                          <geom class="2f85/collision" mesh="spring_link"/>
                          <body name="left_follower" pos="0 0.055 0.0375">
                            <inertial mass="0.0125222" pos="0 -0.011046 0.0124786" quat="1 0.1664 0 0"
                              diaginertia="2.67415e-06 2.4559e-06 6.02031e-07"/>
                            <joint name="left_follower_joint" class="follower"/>
                            <geom class="2f85/visual" mesh="follower" material="black"/>
                            <geom class="2f85/collision" mesh="follower"/>
                            <body name="left_pad" pos="0 -0.0189 0.01352">
                              <geom class="pad_box1" name="left_pad1"/>
                              <geom class="pad_box2" name="left_pad2"/>
                              <inertial mass="0.0035" pos="0 -0.0025 0.0185" quat="1 0 0 1"
                                diaginertia="4.73958e-07 3.64583e-07 1.23958e-07"/>
                              <geom class="2f85/visual" mesh="pad"/>
                              <body name="left_silicone_pad">
                                <geom class="2f85/visual" mesh="silicone_pad" material="black"/>
                              </body>
                            </body>
                          </body>
                        </body>
                      </body>
                    </body>
                  </body>
                </body>
              </body>
            </body>
          </body>
        </body>
      </body>
    </body>
  </worldbody>

  <contact>
    <exclude body1="base" body2="left_driver"/>
    <exclude body1="base" body2="right_driver"/>
    <exclude body1="base" body2="left_spring_link"/>
    <exclude body1="base" body2="right_spring_link"/>
    <exclude body1="right_coupler" body2="right_follower"/>
    <exclude body1="left_coupler" body2="left_follower"/>
  </contact>

  <tendon>
    <fixed name="split">
      <joint joint="right_driver_joint" coef="0.5"/>
      <joint joint="left_driver_joint" coef="0.5"/>
    </fixed>
  </tendon>

  <equality>
    <connect anchor="0 0 0" body1="right_follower" body2="right_coupler" solimp="0.95 0.99 0.001" solref="0.005 1"/>
    <connect anchor="0 0 0" body1="left_follower" body2="left_coupler" solimp="0.95 0.99 0.001" solref="0.005 1"/>
    <joint joint1="right_driver_joint" joint2="left_driver_joint" polycoef="0 1 0 0 0" solimp="0.95 0.99 0.001"
      solref="0.005 1"/>
  </equality>

  <actuator>
    <general class="ur10" name="actuator1" joint="joint1" gainprm="4500" biasprm="0 -4500 -450" forcerange="-330 330"/>
    <general class="ur10" name="actuator2" joint="joint2" gainprm="4500" biasprm="0 -4500 -450" forcerange="-330 330"/>
    <general class="ur10" name="actuator3" joint="joint3" gainprm="3500" biasprm="0 -3500 -350" forcerange="-150 150" ctrlrange="-3.1415 3.1415"/>
    <general class="ur10" name="actuator4" joint="joint4" gainprm="3500" biasprm="0 -3500 -350" forcerange="-56 56"/>
    <general class="ur10" name="actuator5" joint="joint5" gainprm="2000" biasprm="0 -2000 -200" forcerange="-56 56"/>
    <general class="ur10" name="actuator6" joint="joint6" gainprm="2000" biasprm="0 -2000 -200" forcerange="-56 56"/>
    <general class="2f85" name="fingers_actuator" tendon="split" forcerange="-5 5" ctrlrange="0 255"
      gainprm="0.3137255 0 0" biasprm="0 -100 -10"/>
  </actuator>

  <sensor>
    <jointpos name="ur10/joint1_pos" joint="joint1"/>
    <jointpos name="ur10/joint2_pos" joint="joint2"/>
    <jointpos name="ur10/joint3_pos" joint="joint3"/>
    <jointpos name="ur10/joint4_pos" joint="joint4"/>
    <jointpos name="ur10/joint5_pos" joint="joint5"/>
    <jointpos name="ur10/joint6_pos" joint="joint6"/>

    <framepos name="2f85/pinch_pos" objtype="site" objname="pinch"/>
    <framequat name="2f85/pinch_quat" objtype="site" objname="pinch"/>
    <framelinvel name="2f85/pinch_vel" objtype="site" objname="pinch"/>
  </sensor>

</mujoco>