<mujoco model="ur10">
  <compiler angle="radian" autolimits="true"/>

  <default>
    <default class="ur10">
      <joint axis="0 1 0" range="-6.28319 6.28319" armature="0.1"/>
      <position ctrlrange="-6.2831 6.2831"/>
      <general biastype="affine" ctrlrange="-6.2831 6.2831" gainprm="5000" biasprm="0 -5000 -500"/>
    </default>
  </default>

  <asset>
    <mesh name="base0" file="assets/base.stl"/>
    <mesh name="shoulder" file="assets/shoulder.stl"/>
    <mesh name="upperarm" file="assets/upperarm.stl"/>
    <mesh name="forearm" file="assets/forearm.stl"/>
    <mesh name="wrist1" file="assets/wrist1.stl"/>
    <mesh name="wrist2" file="assets/wrist2.stl"/>
    <mesh name="wrist3" file="assets/wrist3.stl"/>
  </asset>

  <worldbody>
    <body name="base0" childclass="ur10">
      <geom quat="-1 0 0 0" type="mesh" rgba="0.7 0.7 0.7 1" mesh="base0"/>
      <body name="shoulder_link" pos="0 0 0.1273" quat="0 0 0 1">
        <inertial pos="0.021 -0.027 0" quat="0.988634 -0.000680926 0.148578 -0.0229591" mass="7.1" diaginertia="0.0353866 0.0352903 0.0202532"/>
        <joint name="joint1" pos="0 0 0" axis="0 0 1" range="-6.28319 6.28319" damping="10"/>
        <geom quat="0 0 0 1" type="mesh" rgba="0.7 0.7 0.7 1" mesh="shoulder"/>
        <body name="upper_arm_link" quat="0.5 0.5 0.5 -0.5">
          <inertial pos="-0.232 0 0.158" quat="0.500033 0.499784 0.489585 0.510381" mass="12.7" diaginertia="0.77068 0.769758 0.0278114"/>
          <joint name="joint2" pos="0 0 0" axis="0 0 1" range="-6.28319 6.28319" damping="10"/>
          <geom pos="0 0 0.220941" quat="0.5 0.5 -0.5 -0.5" type="mesh" rgba="0.7 0.7 0.7 1" mesh="upperarm"/>
          <body name="forearm_link" pos="-0.612 0 0" quat="1 0 0 1">
            <inertial pos="-0.3323 0 0.068" quat="0.492051 0.507971 0.507346 0.492394" mass="4.27" diaginertia="0.30928 0.306743 0.00985709"/>
            <joint name="joint3" pos="0 0 0" axis="0 0 1" range="-3.14159 3.14159" damping="5"/>
            <geom pos="0 0 0.049042" quat="0.5 0.5 -0.5 -0.5" type="mesh" rgba="0.7 0.7 0.7 1" mesh="forearm"/>
            <body name="wrist_1_link" pos="-0.5723 0 0.163941" quat="1 0 0 -1">
              <inertial pos="0 -0.018 0.007" quat="0.525776 0.850564 -0.0100431 9.45801e-05" mass="2" diaginertia="0.00296017 0.00269992 0.00209991"/>
              <joint name="joint4" pos="0 0 0" axis="0 0 1" range="-6.28319 6.28319" damping="2"/>
              <geom pos="0 0 -0.1149" quat="0.707107 0.707107 0 0" type="mesh" rgba="0.7 0.7 0.7 1" mesh="wrist1"/>
              <body name="wrist_2_link" pos="0 -0.1157 -2.37305e-11" quat="0.5 0.5 0.5 -0.5">
                <inertial pos="0 0.018 -0.007" quat="0.525776 0.850564 -0.0100431 9.45801e-05" mass="2" diaginertia="0.00296017 0.00269992 0.00209991"/>
                <joint name="joint5" pos="0 0 0" axis="0 0 1" range="-6.28319 6.28319" damping="2"/>
                <geom pos="0 0 -0.1158" quat="1 0 0 0" type="mesh" rgba="0.7 0.7 0.7 1" mesh="wrist2"/>
                <body name="wrist_3_link" pos="0 0.0922 -1.89105e-11" quat="0.707107 -0.707107 0 0">
                  <inertial pos="0 0 -0.026" quat="0.707107 0 0 0.707107" mass="0.365" diaginertia="0.00041 0.0004 0.00034"/>
                  <joint name="joint6" pos="0 0 0" axis="0 0 1" range="-6.28319 6.28319" damping="2"/>
                  <geom pos="0 0 -0.0922" quat="0.707107 0.707107 0 0" type="mesh" rgba="0.7 0.7 0.7 1" mesh="wrist3"/>
                  <body name="attachment" pos="0 0 0" quat="0.707107 0 0 0.707107"></body>
                </body>
              </body>
            </body>
          </body>
        </body>
      </body>
    </body>
  </worldbody>

  <actuator>
    <general class="ur10" name="actuator1" joint="joint1" gainprm="4500" biasprm="0 -4500 -450" forcerange="-330 330"/>
    <general class="ur10" name="actuator2" joint="joint2" gainprm="4500" biasprm="0 -4500 -450" forcerange="-330 330"/>
    <general class="ur10" name="actuator3" joint="joint3" gainprm="3500" biasprm="0 -3500 -350" forcerange="-150 150" ctrlrange="-3.1415 3.1415"/>
    <general class="ur10" name="actuator4" joint="joint4" gainprm="3500" biasprm="0 -3500 -350" forcerange="-56 56"/>
    <general class="ur10" name="actuator5" joint="joint5" gainprm="2000" biasprm="0 -2000 -200" forcerange="-56 56"/>
    <general class="ur10" name="actuator6" joint="joint6" gainprm="2000" biasprm="0 -2000 -200" forcerange="-56 56"/>
  </actuator>

  <sensor>
    <jointpos name="ur10/joint1_pos" joint="joint1"/>
    <jointpos name="ur10/joint2_pos" joint="joint2"/>
    <jointpos name="ur10/joint3_pos" joint="joint3"/>
    <jointpos name="ur10/joint4_pos" joint="joint4"/>
    <jointpos name="ur10/joint5_pos" joint="joint5"/>
    <jointpos name="ur10/joint6_pos" joint="joint6"/>
  </sensor>

</mujoco>