<mujoco model="ur10_robot">
  <default>
    <default class="robot">
      <default class="motor">
        <joint />
        <motor />
      </default>
      <default class="visual">
        <geom material="visualgeom" contype="0" conaffinity="0" group="2" />
      </default>
      <default class="collision">
        <geom material="collision_material" condim="3" contype="0" conaffinity="1" priority="1" group="1" solref="0.005 1" friction="1 0.01 0.01" />
        <equality solimp="0.99 0.999 1e-05" solref="0.005 1" />
      </default>
    </default>
  </default>

  <compiler angle="radian" />

  <asset>
    <material name="LightGrey" rgba="0.7 0.7 0.7 1.0" />
    <material name="default_material" rgba="0.7 0.7 0.7 1" />
    <material name="collision_material" rgba="1.0 0.28 0.1 0.9" />
    <mesh name="base.stl" file="./collision/base.stl" />
    <mesh name="base.dae" file="./visual/base.dae" />
    <mesh name="shoulder.stl" file="./collision/shoulder.stl" />
    <mesh name="shoulder.dae" file="./visual/shoulder.dae" />
    <mesh name="upperarm.stl" file="./collision/upperarm.stl" />
    <mesh name="upperarm.dae" file="./visual/upperarm.dae" />
    <mesh name="forearm.stl" file="./collision/forearm.stl" />
    <mesh name="forearm.dae" file="./visual/forearm.dae" />
    <mesh name="wrist1.stl" file="./collision/wrist1.stl" />
    <mesh name="wrist1.dae" file="./visual/wrist1.dae" />
    <mesh name="wrist2.stl" file="./collision/wrist2.stl" />
    <mesh name="wrist2.dae" file="./visual/wrist2.dae" />
    <mesh name="wrist3.stl" file="./collision/wrist3.stl" />
    <mesh name="wrist3.dae" file="./visual/wrist3.dae" />
  </asset>

  <worldbody>
    <body name="base_link" pos="0.00000000 0.00000000 0.00000000" quat="1 0 0 0" childclass="robot">
      <freejoint name="floating_base" />
      <body name="base_link_inertia" pos="0 0 0" quat="6.123233995736766e-17 0.0 0.0 1.0">
        <inertial pos="0 0 0" quat="1.0 0.0 0.0 0.0" mass="4.0" diaginertia="0.0061063308908 0.0061063308908 0.01125" />
        <geom name="base_link_inertia_collision" pos="0 0 0" quat="6.123233995736766e-17 0.0 0.0 1.0" type="mesh" mesh="base.stl" class="collision" />
        <geom name="base_link_inertia_visual" pos="0 0 0" quat="6.123233995736766e-17 0.0 0.0 1.0" material="LightGrey" type="mesh" mesh="base.dae" class="visual" />
        <body name="shoulder_link" pos="0 0 0.1273" quat="1.0 0.0 0.0 0.0">
          <joint name="shoulder_pan_joint" type="hinge" ref="0.0" class="motor" range="-6.283185307179586 6.283185307179586" axis="0 0 1" />
          <inertial pos="0.021 -0.027 0.0" quat="0.7071067811865474 0.7071067811865477 0.0 0.0" mass="7.1" diaginertia="0.03408 0.03529 0.02156" />
          <geom name="shoulder_link_collision" pos="0 0 0" quat="6.123233995736766e-17 0.0 0.0 1.0" type="mesh" mesh="shoulder.stl" class="collision" />
          <geom name="shoulder_link_visual" pos="0 0 0" quat="6.123233995736766e-17 0.0 0.0 1.0" material="LightGrey" type="mesh" mesh="shoulder.dae" class="visual" />
          <body name="upper_arm_link" pos="0 0 0" quat="0.7071067811140325 0.7071067812590626 0.0 0.0">
            <joint name="shoulder_lift_joint" type="hinge" ref="0.0" class="motor" range="-6.283185307179586 6.283185307179586" axis="0 0 1" />
            <inertial pos="-0.232 0.0 0.158" quat="1.0 0.0 0.0 0.0" mass="12.7" diaginertia="0.02814 0.77068 0.76943" />
            <geom name="upper_arm_link_collision" pos="0 0 0.220941" quat="0.5000000000000001 0.5 -0.4999999999999999 -0.5" type="mesh" mesh="upperarm.stl" class="collision" />
            <geom name="upper_arm_link_visual" pos="0 0 0.220941" quat="0.5000000000000001 0.5 -0.4999999999999999 -0.5" material="LightGrey" type="mesh" mesh="upperarm.dae" class="visual" />
            <body name="forearm_link" pos="-0.612 0 0" quat="1.0 0.0 0.0 0.0">
              <joint name="elbow_joint" type="hinge" ref="0.0" class="motor" range="-3.141592653589793 3.141592653589793" axis="0 0 1" />
              <inertial pos="-0.3323 0.0 0.068" quat="1.0 0.0 0.0 0.0" mass="4.27" diaginertia="0.01014 0.30928 0.30646" />
              <geom name="forearm_link_collision" pos="0 0 0.049042" quat="0.5000000000000001 0.5 -0.4999999999999999 -0.5" type="mesh" mesh="forearm.stl" class="collision" />
              <geom name="forearm_link_visual" pos="0 0 0.049042" quat="0.5000000000000001 0.5 -0.4999999999999999 -0.5" material="LightGrey" type="mesh" mesh="forearm.dae" class="visual" />
              <body name="wrist_1_link" pos="-0.5723 0 0.163941" quat="1.0 0.0 0.0 0.0">
                <joint name="wrist_1_joint" type="hinge" ref="0.0" class="motor" range="-6.283185307179586 6.283185307179586" axis="0 0 1" />
                <inertial pos="0.0 -0.018 0.007" quat="0.7071067811865474 0.7071067811865477 0.0 0.0" mass="2.0" diaginertia="0.00296 0.00222 0.00258" />
                <geom name="wrist_1_link_collision" pos="0 0 -0.1149" quat="0.7071067811865476 0.7071067811865475 0.0 0.0" type="mesh" mesh="wrist1.stl" class="collision" />
                <geom name="wrist_1_link_visual" pos="0 0 -0.1149" quat="0.7071067811865476 0.7071067811865475 0.0 0.0" material="LightGrey" type="mesh" mesh="wrist1.dae" class="visual" />
                <body name="wrist_2_link" pos="0 -0.1157 -2.373046667922381e-11" quat="0.7071067811140325 0.7071067812590626 0.0 0.0">
                  <joint name="wrist_2_joint" type="hinge" ref="0.0" class="motor" range="-6.283185307179586 6.283185307179586" axis="0 0 1" />
                  <inertial pos="0.0 0.018 -0.007" quat="0.7071067811865474 -0.7071067811865477 0.0 0.0" mass="2.0" diaginertia="0.00296 0.00222 0.00258" />
                  <geom name="wrist_2_link_collision" pos="0 0 -0.1158" quat="1.0 0.0 0.0 0.0" type="mesh" mesh="wrist2.stl" class="collision" />
                  <geom name="wrist_2_link_visual" pos="0 0 -0.1158" quat="1.0 0.0 0.0 0.0" material="LightGrey" type="mesh" mesh="wrist2.dae" class="visual" />
                  <body name="wrist_3_link" pos="0 0.0922 -1.891053610911353e-11" quat="0.7071067811140325 -0.7071067812590626 8.659560562354933e-17 8.880527684815676e-27">
                    <joint name="wrist_3_joint" type="hinge" ref="0.0" class="motor" range="-6.283185307179586 6.283185307179586" axis="0 0 1" />
                    <inertial pos="0.0 0 -0.026" quat="1.0 0.0 0.0 0.0" mass="0.365" diaginertia="0.0004 0.00041 0.00034" />
                    <geom name="wrist_3_link_collision" pos="0 0 -0.0922" quat="0.7071067811865476 0.7071067811865475 0.0 0.0" type="mesh" mesh="wrist3.stl" class="collision" />
                    <geom name="wrist_3_link_visual" pos="0 0 -0.0922" quat="0.7071067811865476 0.7071067811865475 0.0 0.0" material="LightGrey" type="mesh" mesh="wrist3.dae" class="visual" />
                    <body name="flange" pos="0 0 0" quat="0.5000000000000001 -0.4999999999999999 -0.5 -0.5">
                      <body name="tool0" pos="0 0 0" quat="0.5000000000000001 0.5 0.4999999999999999 0.5" />
                    </body>
                  </body>
                </body>
              </body>
            </body>
          </body>
        </body>
      </body>
      <body name="base" pos="0 0 0" quat="6.123233995736766e-17 0.0 0.0 1.0" />
      <site name="base_link_site" pos="0 0 0" quat="1 0 0 0" />
      <camera name="front_camera" mode="track" fovy="90.0" quat="4.329780281177467e-17 4.329780281177466e-17 0.7071067811865475 0.7071067811865476" pos="0.0 2.0 0.5" />
      <camera name="side_camera" mode="track" fovy="90.0" quat="-0.5 -0.4999999999999999 0.5 0.5000000000000001" pos="-2.0 0.0 0.5" />
    </body>
  </worldbody>

  <actuator>
    <motor name="shoulder_pan_joint_ctrl" joint="shoulder_pan_joint" class="motor" />
    <motor name="shoulder_lift_joint_ctrl" joint="shoulder_lift_joint" class="motor" />
    <motor name="elbow_joint_ctrl" joint="elbow_joint" class="motor" />
    <motor name="wrist_1_joint_ctrl" joint="wrist_1_joint" class="motor" />
    <motor name="wrist_2_joint_ctrl" joint="wrist_2_joint" class="motor" />
    <motor name="wrist_3_joint_ctrl" joint="wrist_3_joint" class="motor" />
  </actuator>

  <contact>
    <exclude body1="base_link_inertia" body2="shoulder_link" />
    <exclude body1="shoulder_link" body2="upper_arm_link" />
    <exclude body1="upper_arm_link" body2="forearm_link" />
    <exclude body1="forearm_link" body2="wrist_1_link" />
    <exclude body1="wrist_1_link" body2="wrist_2_link" />
    <exclude body1="wrist_2_link" body2="wrist_3_link" />
  </contact>

  <sensor>
    <framepos name="base_link_site_pos" objtype="site" objname="base_link_site" />
    <framequat name="base_link_site_quat" objtype="site" objname="base_link_site" />
    <framelinvel name="base_link_site_linvel" objtype="site" objname="base_link_site" />
    <frameangvel name="base_link_site_angvel" objtype="site" objname="base_link_site" />
    <velocimeter name="base_link_site_vel" site="base_link_site" />
  </sensor>
</mujoco>